Workbook

Sheet Sheet2
A1: Employee ID | B1: Employee Name | C1: Gender | D1: Department | E1: Branch | F1: Years of Experience | G1: Sales ($) | H1: Performance | I1: Status
A2: EMP001 | B2: John Adams | C2: Male | D2: Sales | E2: Lagos | F2: 5 | G2: 12500 | H2: Excellent | I2: Completed
A3: EMP002 | B3: Sarah James | C3: Female | D3: Marketing | E3: Abuja | F3: 3 | G3: 9800 | H3: Good | I3: Completed
A4: EMP003 | B4: David Paul | C4: Male | D4: Sales | E4: Lagos | F4: 7 | G4: 15400 | H4: Excellent | I4: Completed
A5: EMP004 | B5: Grace John | C5: Female | D5: HR | E5: Port Harcourt | F5: 4 | G5: 7200 | H5: Good | I5: Pending
A6: EMP005 | B6: Michael Obi | C6: Male | D6: Finance | E6: Abuja | F6: 6 | G6: 13200 | H6: Excellent | I6: Completed
A7: EMP006 | B7: Esther Bello | C7: Female | D7: Sales | E7: Lagos | F7: 2 | G7: 8600 | H7: Fair | I7: Pending
A8: EMP007 | B8: Daniel Kim | C8: Male | D8: Marketing | E8: Lagos | F8: 8 | G8: 16800 | H8: Excellent | I8: Completed
A9: EMP008 | B9: Mercy Ali | C9: Female | D9: Finance | E9: Port Harcourt | F9: 5 | G9: 11900 | H9: Good | I9: Completed
A10: EMP009 | B10: James Cole | C10: Male | D10: HR | E10: Abuja | F10: 1 | G10: 6500 | H10: Fair | I10: Pending
A11: EMP010 | B11: Vivian Duke | C11: Female | D11: Sales | E11: Lagos | F11: 9 | G11: 18200 | H11: Excellent | I11: Completed
A12: EMP011 | B12: Peter Simon | C12: Male | D12: Finance | E12: Lagos | F12: 4 | G12: 11000 | H12: Good | I12: Completed
A13: EMP012 | B13: Anita Grace | C13: Female | D13: Marketing | E13: Abuja | F13: 6 | G13: 13600 | H13: Excellent | I13: Completed
... A21: EMP020 | B21: Faith Williams | C21: Female | D21: Marketing | E21: Lagos | F21: 4 | G21: 10500 | H21: Good | I21: Pending

Sheet Sheet1
A1: Name, Department, and Branch | B1: Left | C1: Right | D1: Bonus
A2: =_xlfn.CONCAT(Sheet2!B2, " - ",Sheet2!D2, " - ",Sheet2!E2) -> John Adams - Sales - Lagos | B2: =LEFT(Sheet2!B2,4) -> John | C2: =RIGHT(Sheet2!B2,5) -> Adams | D2: =IF(Sheet2!G2>=15000,1000,IF(Sheet2!G2>=1000,500,0)) -> 500
A3: =_xlfn.CONCAT(Sheet2!B3, " - ",Sheet2!D3, " - ",Sheet2!E3) -> Sarah James - Marketing - Abuja | B3: =LEFT(Sheet2!B3,4) -> Sara | C3: =RIGHT(Sheet2!B3,5) -> James | D3: =IF(Sheet2!G3>=15000,1000,IF(Sheet2!G3>=1000,500,0)) -> 500
A4: =_xlfn.CONCAT(Sheet2!B4, " - ",Sheet2!D4, " - ",Sheet2!E4) -> David Paul - Sales - Lagos | B4: =LEFT(Sheet2!B4,4) -> Davi | C4: =RIGHT(Sheet2!B4,5) -> Paul | D4: =IF(Sheet2!G4>=15000,1000,IF(Sheet2!G4>=1000,500,0)) -> 1000
A5: =_xlfn.CONCAT(Sheet2!B5, " - ",Sheet2!D5, " - ",Sheet2!E5) -> Grace John - HR - Port Harcourt | B5: =LEFT(Sheet2!B5,4) -> Grac | C5: =RIGHT(Sheet2!B5,5) -> John | D5: =IF(Sheet2!G5>=15000,1000,IF(Sheet2!G5>=1000,500,0)) -> 500
A6: =_xlfn.CONCAT(Sheet2!B6, " - ",Sheet2!D6, " - ",Sheet2!E6) -> Michael Obi - Finance - Abuja | B6: =LEFT(Sheet2!B6,4) -> Mich | C6: =RIGHT(Sheet2!B6,5) -> l Obi | D6: =IF(Sheet2!G6>=15000,1000,IF(Sheet2!G6>=1000,500,0)) -> 500
A7: =_xlfn.CONCAT(Sheet2!B7, " - ",Sheet2!D7, " - ",Sheet2!E7) -> Esther Bello - Sales - Lagos | B7: =LEFT(Sheet2!B7,4) -> Esth | C7: =RIGHT(Sheet2!B7,5) -> Bello | D7: =IF(Sheet2!G7>=15000,1000,IF(Sheet2!G7>=1000,500,0)) -> 500
A8: =_xlfn.CONCAT(Sheet2!B8, " - ",Sheet2!D8, " - ",Sheet2!E8) -> Daniel Kim - Marketing - Lagos | B8: =LEFT(Sheet2!B8,4) -> Dani | C8: =RIGHT(Sheet2!B8,5) -> l Kim | D8: =IF(Sheet2!G8>=15000,1000,IF(Sheet2!G8>=1000,500,0)) -> 1000
A9: =_xlfn.CONCAT(Sheet2!B9, " - ",Sheet2!D9, " - ",Sheet2!E9) -> Mercy Ali - Finance - Port Harcourt | B9: =LEFT(Sheet2!B9,4) -> Merc | C9: =RIGHT(Sheet2!B9,5) -> y Ali | D9: =IF(Sheet2!G9>=15000,1000,IF(Sheet2!G9>=1000,500,0)) -> 500
A10: =_xlfn.CONCAT(Sheet2!B10, " - ",Sheet2!D10, " - ",Sheet2!E10) -> James Cole - HR - Abuja | B10: =LEFT(Sheet2!B10,4) -> Jame | C10: =RIGHT(Sheet2!B10,5) -> Cole | D10: =IF(Sheet2!G10>=15000,1000,IF(Sheet2!G10>=1000,500,0)) -> 500
A11: =_xlfn.CONCAT(Sheet2!B11, " - ",Sheet2!D11, " - ",Sheet2!E11) -> Vivian Duke - Sales - Lagos | B11: =LEFT(Sheet2!B11,4) -> Vivi | C11: =RIGHT(Sheet2!B11,5) -> Duke | D11: =IF(Sheet2!G11>=15000,1000,IF(Sheet2!G11>=1000,500,0)) -> 1000
A12: =_xlfn.CONCAT(Sheet2!B12, " - ",Sheet2!D12, " - ",Sheet2!E12) -> Peter Simon - Finance - Lagos | B12: =LEFT(Sheet2!B12,4) -> Pete | C12: =RIGHT(Sheet2!B12,5) -> Simon | D12: =IF(Sheet2!G12>=15000,1000,IF(Sheet2!G12>=1000,500,0)) -> 500
A13: =_xlfn.CONCAT(Sheet2!B13, " - ",Sheet2!D13, " - ",Sheet2!E13) -> Anita Grace - Marketing - Abuja | B13: =LEFT(Sheet2!B13,4) -> Anit | C13: =RIGHT(Sheet2!B13,5) -> Grace | D13: =IF(Sheet2!G13>=15000,1000,IF(Sheet2!G13>=1000,500,0)) -> 500
... A21: =_xlfn.CONCAT(Sheet2!B21, " - ",Sheet2!D21, " - ",Sheet2!E21) -> Faith Williams - Marketing - Lagos | B21: =LEFT(Sheet2!B21,4) -> Fait | C21: =RIGHT(Sheet2!B21,5) -> liams | D21: =IF(Sheet2!G21>=15000,1000,IF(Sheet2!G21>=1000,500,0)) -> 500
A24: 1 DETERMING
B25: The total number of employees. | D25: =COUNTA(Sheet2!A2:A21) -> 20
B26: The number of male employees. | D26: =COUNTIF(Sheet2!C2:C21,"Male") -> 10
B27: The number of female employees | D27: =COUNTIF(Sheet2!C2:C21,"Female") -> 10
B28: The number of employees with Completed status. | D28: =COUNTIF(Sheet2!I2:I21,"Completed") -> 14
B29: The number of employees with Pending status | D29: =COUNTIF(Sheet2!I2:I21,"Pending") -> 6
A30: 2 FIND
B31: The highest sales value | D31: =MAX(Sheet2!G2:G21) -> 19500
B32: The lowest sales value | D32: =MIN(Sheet2!G2:G21) -> 6500
B33: The average sales value. | D33: =AVERAGE(Sheet2!G2:G21) -> 12100
A35: 3 TOTAL SALES | B35: Generated by lagos branch. | D35: =SUMIF(Sheet2!E2:E21,"lagos",Sheet2!G2:G21) -> 131500
B36: Generated by Abuja branch. | D36: =SUMIF(Sheet2!E2:E21,"Abuja",Sheet2!G2:G21) -> 69300
B37: Generated by Port Harcourt branch. | D37: =SUMIF(Sheet2!E2:E21,"Port Harcourt",Sheet2!G2:G21) -> 41200
A39: 4 AVERAGE SALES | B39: HR department | D39: =AVERAGEIF(Sheet2!D2:D21,"HR",Sheet2!G2:G21) -> 8875
B40: Sales department | D40: =AVERAGEIF(Sheet2!D2:D21,"Sales",Sheet2!G2:G21) -> 14014.286
B41: Marketing department | D41: =AVERAGEIF(Sheet2!D3:D21,"Marketing",Sheet2!G2:G21) -> 12100
B42: Finance department | D42: =AVERAGEIF(Sheet2!D2:D21,"Finance",Sheet2!G2:G21) -> 11250
A46: 5 HIGHEST SALES | B46: Determine the highest and lowest sales recorded in each department.
B47: Highest sales in HR departmet | D47: =_xlfn.MAXIFS(Sheet2!G2:G21,Sheet2!D2:D21,"HR") -> 11700
B48: Highest sales in Sales departmet | D48: =_xlfn.MAXIFS(Sheet2!G2:G21,Sheet2!D2:D21,"Sales") -> 19500
B49: Highest sales in Marketing departmet | D49: =_xlfn.MAXIFS(Sheet2!G2:G21,Sheet2!D2:D21,"Marketing") -> 16800
B50: Highest sales in Finance department | D50: =_xlfn.MAXIFS(Sheet2!G2:G21,Sheet2!D2:D21,"Finance") -> 13200
A53: 6 LOWEST SALES | B53: Lowest sales in HR departmet | D53: =_xlfn.MINIFS(Sheet2!G2:G21,Sheet2!D2:D21,"HR") -> 6500
B54: Lowest sales in Sales departmet | D54: =_xlfn.MINIFS(Sheet2!G2:G21,Sheet2!D2:D21,"sales") -> 8600
B55: Lowest sales in Marketing departmet | D55: =_xlfn.MINIFS(Sheet2!G2:G21,Sheet2!D2:D21,"Marketing") -> 9800
B56: Lowest sales in Finance department | D56: =_xlfn.MINIFS(Sheet2!G2:G21,Sheet2!D2:D21,"Finance") -> 8900
...
