Workbook
Name Slicer_Category: #N/A
Name Slicer_Channel: #N/A
Name Slicer_Months__Order_Date: #N/A
Name Slicer_Regions: #N/A
Name Slicer_Years__Order_Date: #N/A

Sheet Sales_Transactions
A1: Order_ID | B1: Order_Date | C1: Customer_ID | D1: Product_ID | E1: Store_ID | F1: Channel | G1: Quantity | H1: Unit_Price | I1: Discount | J1: Payment_Method
A2: ORD-10001 | B2: 46174 | C2: CUST-00070 | D2: PROD-0044 | E2: ST-008 | F2: Physical Store | G2: 1 | H2: 503.99 | I2: 0.02 | J2: Mobile Money
A3: ORD-10002 | B3: 46174 | C3: CUST-00041 | D3: PROD-0040 | E3: ST-003 | F3: Physical Store | G3: 3 | H3: 99 | I3: 0.1 | J3: Transfer
A4: ORD-10003 | B4: 45974 | C4: CUST-00686 | D4: PROD-0046 | E4: ST-011 | F4: Online | G4: 2 | H4: 79.79 | I4: 5% | J4: Transfer
A5: ORD-10004 | B5: 46104 | C5: CUST-00324 | D5: PROD-0060 | E5: ST-003 | F5: Online | G5: 2 | H5: 111.18 | I5: 0 | J5: Card
A6: ORD-10005 | B6: 46145 | C6: CUST-00219 | D6: PROD-0033 | E6: ST-009 | F6: Online | G6: 6 | H6: 2523.99 | I6: 0 | J6: Cash
A7: ORD-10006 | B7: 46059 | C7: CUST-00292 | D7: PROD-0011 | E7: ST-015 | F7: Physical Store | G7: 3 | H7: 1917.99 | I7: 0 | J7: mobile money
A8: ORD-10007 | B8: 46023 | C8: CUST-00680 | D8: PROD-0007 | E8: ST-005 | F8: Physical Store | G8: 1 | H8: 1799 | I8: 0 | J8: Mobile Money
A9: ORD-10008 | B9: 45949 | C9: CUST-00279 | D9: PROD-0019 | E9: ST-020 | F9: Online | G9: 4 | H9: 304.98 | I9: 0.02 | J9: Transfer
A10: ORD-10009 | B10: 46128 | C10: CUST-00501 | D10: PROD-0017 | E10: ST-002 | F10: Online | G10: 3 | H10: 1008.99 | I10: 0.05 | J10: Card
A11: ORD-10010 | B11: 45871 | D11: PROD-0050 | E11: ST-005 | F11: Physical Store | G11: 1 | H11: 115.43 | I11: 0.2 | J11: Mobile Money
A12: ORD-10011 | B12: 46231 | C12: CUST-00438 | D12: PROD-0036 | E12: ST-001 | F12: Online | G12: 1 | H12: 1234.97 | I12: 0 | J12: Mobile Money
A13: ORD-10012 | B13: 45888 | C13: CUST-00379 | D13: PROD-0038 | E13: ST-018 | F13: Online | G13: 2 | H13: 244.02 | I13: 0 | J13: Transfer
A14: ORD-10013 | B14: 46056 | C14: CUST-00041 | E14: ST-012 | F14: Online | G14: 3 | H14: 146,066 | I14: 0 | J14: Transfer
A15: ORD-10014 | B15: 46156 | C15: CUST-00417 | D15: PROD-0040 | E15: ST-005 | F15: Online | G15: 5 | H15: 101.97 | I15: 0 | J15: USSD
A16: ORD-10015 | B16: 45882 | C16: CUST-00184 | D16: PROD-0048 | E16: ST-011 | F16: Physical Store | G16: 4 | H16: 117.81 | I16: 0.02 | J16: Transfer
A17: ORD-10016 | B17: 45951 | C17: CUST-00719 | D17: PROD-0007 | E17: ST-013 | F17: Online | G17: 5 | H17: 1799 | I17: 0.02 | J17: Cash
A18: ORD-10017 | B18: 46105 | C18: CUST-00359 | D18: PROD-0020 | E18: ST-008 | F18: Online | G18: 1 | H18: 399 | I18: 0.02 | J18: USSD
A19: ORD-10018 | B19: 46038 | C19: CUST-00286 | D19: PROD-0056 | E19: ST-003 | F19: Physical Store | G19: 2 | H19: 157.41 | I19: 0.15 | J19: Mobile Money
A20: ORD-10019 | B20: 46039 | C20: CUST-00029 | D20: PROD-0008 | E20: ST-009 | F20: Online | G20: 3 | H20: 2367.97 | I20: 0.05 | J20: CARD
A21: ORD-10020 | B21: 45925 | C21: CUST-00611 | D21: PROD-0028 | E21: ST-012 | F21: Physical Store | G21: 2 | H21: 999 | I21: 0 | J21: USSD
A22: ORD-10021 | B22: 46165 | C22: CUST-00195 | D22: PROD-0017 | E22: ST-002 | F22: Physical Store | G22: 1 | H22: 969.03 | I22: 0.02 | J22: Transfer
A23: ORD-10022 | B23: 46090 | C23: CUST-00072 | D23: PROD-0043 | E23: ST-011 | F23: Physical Store | G23: 3 | H23: 307.97 | I23: 0 | J23: Transfer
A24: ORD-10023 | B24: 46129 | C24: CUST-00317 | D24: PROD-0043 | E24: ST-014 | F24: Physical Store | G24: 2 | H24: 304.98 | I24: 0.05 | J24: Mobile Money
A25: ORD-10024 | B25: 45935 | C25: CUST-00197 | D25: PROD-0027 | E25: ST-013 | F25: Online | G25: 3 | H25: 1357.03 | I25: 0.05 | J25: USSD
A26: ORD-10025 | B26: 46150 | C26: CUST-00001 | D26: PROD-0020 | E26: ST-010 | F26: Online | G26: 2 | H26: 410.97 | I26: 0.1 | J26: USSD
... A49: ORD-10048 | B49: 46029 | C49: CUST-00111 | D49: PROD-0038 | E49: ST-001 | F49: Physical Store | G49: 3 | H49: 253.98 | I49: 0.15 | J49: USSD
A50: ORD-10049 | B50: 45971 | C50: CUST-00078 | E50: ST-008 | F50: Online | G50: 3 | H50: 375779 | I50: 0.05 | J50: Mobile Money
A51: ORD-10050 | B51: 45931 | C51: CUST-00580 | D51: PROD-0051 | E51: ST-002 | F51: Physical Store | G51: 3 | H51: 86.33 | I51: 0.1 | J51: Card
A52: ORD-10051 | B52: 46129 | C52: CUST-00664 | D52: PROD-0022 | E52: ST-001 | F52: Physical Store | G52: 4 | H52: 1286.01 | I52: 0 | J52: USSD
A53: ORD-10052 | B53: 46055 | C53: CUST-00651 | D53: PROD-0058 | E53: ST-015 | F53: Online | G53: 2 | H53: 80.58 | I53: 0.05 | J53: Mobile Money
A54: ORD-10053 | B54: 46145 | C54: CUST-00794 | D54: PROD-0031 | E54: ST-015 | F54: Physical Store | G54: 4 | H54: 1599 | I54: 0.05 | J54: Transfer
A55: ORD-10054 | B55: 45995 | C55: CUST-00089 | D55: PROD-0018 | E55: ST-015 | F55: Online | G55: 4 | H55: 874.47 | I55: 0.15 | J55: Transfer
A56: ORD-10055 | B56: 45884 | C56: CUST-00507 | D56: PROD-0055 | E56: ST-011 | F56: Online | G56: 2 | H56: 97.02 | I56: 0.1 | J56: Transfer
A57: ORD-10056 | B57: 46044 | C57: CUST-00287 | D57: PROD-0057 | E57: ST-020 | F57: Physical Store | G57: 3 | H57: 127.71 | I57: 0.02 | J57: Card
A58: ORD-10057 | B58: 45993 | C58: CUST-00738 | D58: PROD-0027 | E58: ST-016 | F58: Online | G58: 3 | H58: 1399 | I58: 0.2 | J58: USSD
A59: ORD-10058 | B59: 45878 | C59: CUST-00096 | D59: PROD-0019 | E59: ST-008 | F59: Physical Store | G59: 3 | H59: 301.99 | I59: 0.05 | J59: Mobile Money
A60: ORD-10059 | B60: 46058 | C60: CUST-00485 | D60: PROD-0036 | E60: ST-017 | F60: Physical Store | G60: 2 | H60: 1187.01 | I60: 0.1 | J60: Transfer
A61: ORD-10060 | B61: 46229 | C61: CUST-00465 | D61: PROD-0018 | E61: ST-010 | F61: Physical Store | G61: 1 | H61: 832.02 | I61: 0.02 | J61: Transfer
A62: ORD-10061 | B62: 45931 | C62: CUST-00761 | D62: PROD-0035 | E62: ST-006 | F62: Online | G62: 1 | H62: 1018.98 | I62: 0.2 | J62: Transfer
...

Sheet Cleaned_S_T
A1: Order_ID | B1: Order_Date | C1: Customer_ID | D1: Customer Segement | E1: Product_ID | F1: Category | G1: Regions | H1: Store_ID | I1: Channel | J1: Quantity | K1: Unit_Price | L1: Discount | M1: Payment_Method | N1: Cost Price | O1: Revenue | P1: Profit | Q1: Profit Margin | R1: COGS
A2: ORD-10001 | B2: 46028 | C2: CUST-00070 | D2: =VLOOKUP(C2,Customers!A:E,5,FALSE) -> Affluent | E2: PROD-0044 | F2: =VLOOKUP(Table1[[#This Row],[Product_ID]],Products!A:D,4,FALSE) -> Audio | G2: =VLOOKUP(H2,Stores!A:E,5,FALSE) -> Asia | H2: ST-008 | I2: Physical Store | J2: 1 | K2: 503.99 | L2: 0.02 | M2: Transfer | N2: 354.29 | O2: =Table1[[#This Row],[Unit_Price]]*Table1[[#This Row],[Quantity]] -> 503.99 | P2: =Table1[[#This Row],[Revenue]]-Table1[[#This Row],[COGS]] -> 149.7 | Q2: =Table1[[#This Row],[Profit]]/Table1[[#This Row],[Revenue]] -> 0.2970297 | R2: =Table1[[#This Row],[Cost Price]]*Table1[[#This Row],[Quantity]] -> 354.29
A3: ORD-10002 | B3: 46028 | C3: CUST-00041 | D3: =VLOOKUP(C3,Customers!A:E,5,FALSE) -> Mass Market | E3: PROD-0040 | F3: =VLOOKUP(Table1[[#This Row],[Product_ID]],Products!A:D,4,FALSE) -> Audio | G3: =VLOOKUP(H3,Stores!A:E,5,FALSE) -> Africa | H3: ST-003 | I3: Physical Store | J3: 3 | K3: 99 | L3: 0.1 | M3: Transfer | N3: 71.28 | O3: =Table1[[#This Row],[Unit_Price]]*Table1[[#This Row],[Quantity]] -> 297 | P3: =Table1[[#This Row],[Revenue]]-Table1[[#This Row],[COGS]] -> 83.16 | Q3: =Table1[[#This Row],[Profit]]/Table1[[#This Row],[Revenue]] -> 0.28 | R3: =Table1[[#This Row],[Cost Price]]*Table1[[#This Row],[Quantity]] -> 213.84
A4: ORD-10003 | B4: 45974 | C4: CUST-00686 | D4: =VLOOKUP(C4,Customers!A:E,5,FALSE) -> Mass Affluent | E4: PROD-0046 | F4: =VLOOKUP(Table1[[#This Row],[Product_ID]],Products!A:D,4,FALSE) -> Audio | G4: =VLOOKUP(H4,Stores!A:E,5,FALSE) -> Europe | H4: ST-011 | I4: Online | J4: 2 | K4: 79.79 | L4: 0.05 | M4: Transfer | N4: 57.67 | O4: =Table1[[#This Row],[Unit_Price]]*Table1[[#This Row],[Quantity]] -> 159.58 | P4: =Table1[[#This Row],[Revenue]]-Table1[[#This Row],[COGS]] -> 44.24 | Q4: =Table1[[#This Row],[Profit]]/Table1[[#This Row],[Revenue]] -> 0.27722772 | R4: =Table1[[#This Row],[Cost Price]]*Table1[[#This Row],[Quantity]] -> 115.34
A5: ORD-10004 | B5: 46104 | C5: CUST-00324 | D5: =VLOOKUP(C5,Customers!A:E,5,FALSE) -> Affluent | E5: PROD-0060 | F5: =VLOOKUP(Table1[[#This Row],[Product_ID]],Products!A:D,4,FALSE) -> Accessories | G5: =VLOOKUP(H5,Stores!A:E,5,FALSE) -> Africa | H5: ST-003 | I5: Online | J5: 2 | K5: 111.18 | L5: 0 | M5: Card | N5: 78.48 | O5: =Table1[[#This Row],[Unit_Price]]*Table1[[#This Row],[Quantity]] -> 222.36 | P5: =Table1[[#This Row],[Revenue]]-Table1[[#This Row],[COGS]] -> 65.4 | Q5: =Table1[[#This Row],[Profit]]/Table1[[#This Row],[Revenue]] -> 0.29411765 | R5: =Table1[[#This Row],[Cost Price]]*Table1[[#This Row],[Quantity]] -> 156.96
A6: ORD-10005 | B6: 46086 | C6: CUST-00219 | D6: =VLOOKUP(C6,Customers!A:E,5,FALSE) -> Mass Market | E6: PROD-0033 | F6: =VLOOKUP(Table1[[#This Row],[Product_ID]],Products!A:D,4,FALSE) -> Laptops | G6: =VLOOKUP(H6,Stores!A:E,5,FALSE) -> Asia | H6: ST-009 | I6: Online | J6: 6 | K6: 2523.99 | L6: 0 | M6: Cash | N6: 1599.36 | O6: =Table1[[#This Row],[Unit_Price]]*Table1[[#This Row],[Quantity]] -> 15143.94 | P6: =Table1[[#This Row],[Revenue]]-Table1[[#This Row],[COGS]] -> 5547.78 | Q6: =Table1[[#This Row],[Profit]]/Table1[[#This Row],[Revenue]] -> 0.36633663 | R6: =Table1[[#This Row],[Cost Price]]*Table1[[#This Row],[Quantity]] -> 9596.16
A7: ORD-10006 | B7: 46175 | C7: CUST-00292 | D7: =VLOOKUP(C7,Customers!A:E,5,FALSE) -> Mass Market | E7: PROD-0011 | F7: =VLOOKUP(Table1[[#This Row],[Product_ID]],Products!A:D,4,FALSE) -> Televisions | G7: =VLOOKUP(H7,Stores!A:E,5,FALSE) -> North America | H7: ST-015 | I7: Physical Store | J7: 3 | K7: 1917.99 | L7: 0 | M7: Transfer | N7: 1177.38 | O7: =Table1[[#This Row],[Unit_Price]]*Table1[[#This Row],[Quantity]] -> 5753.97 | P7: =Table1[[#This Row],[Revenue]]-Table1[[#This Row],[COGS]] -> 2221.83 | Q7: =Table1[[#This Row],[Profit]]/Table1[[#This Row],[Revenue]] -> 0.38613861 | R7: =Table1[[#This Row],[Cost Price]]*Table1[[#This Row],[Quantity]] -> 3532.14
A8: ORD-10007 | B8: 46023 | C8: CUST-00680 | D8: =VLOOKUP(C8,Customers!A:E,5,FALSE) -> Mass Market | E8: PROD-0007 | F8: =VLOOKUP(Table1[[#This Row],[Product_ID]],Products!A:D,4,FALSE) -> Televisions | G8: =VLOOKUP(H8,Stores!A:E,5,FALSE) -> Africa | H8: ST-005 | I8: Physical Store | J8: 1 | K8: 1799 | L8: 0 | M8: Transfer | N8: 1097.39 | O8: =Table1[[#This Row],[Unit_Price]]*Table1[[#This Row],[Quantity]] -> 1799 | P8: =Table1[[#This Row],[Revenue]]-Table1[[#This Row],[COGS]] -> 701.61 | Q8: =Table1[[#This Row],[Profit]]/Table1[[#This Row],[Revenue]] -> 0.39 | R8: =Table1[[#This Row],[Cost Price]]*Table1[[#This Row],[Quantity]] -> 1097.39
A9: ORD-10008 | B9: 45949 | C9: CUST-00279 | D9: =VLOOKUP(C9,Customers!A:E,5,FALSE) -> Mass Affluent | E9: PROD-0019 | F9: =VLOOKUP(Table1[[#This Row],[Product_ID]],Products!A:D,4,FALSE) -> Smartphones | G9: =VLOOKUP(H9,Stores!A:E,5,FALSE) -> oceania | H9: ST-020 | I9: Online | J9: 4 | K9: 304.98 | L9: 0.02 | M9: Transfer | N9: 194.35 | O9: =Table1[[#This Row],[Unit_Price]]*Table1[[#This Row],[Quantity]] -> 1219.92 | P9: =Table1[[#This Row],[Revenue]]-Table1[[#This Row],[COGS]] -> 442.52 | Q9: =Table1[[#This Row],[Profit]]/Table1[[#This Row],[Revenue]] -> 0.3627451 | R9: =Table1[[#This Row],[Cost Price]]*Table1[[#This Row],[Quantity]] -> 777.4
A10: ORD-10009 | B10: 46128 | C10: CUST-00501 | D10: =VLOOKUP(C10,Customers!A:E,5,FALSE) -> Mass Market | E10: PROD-0017 | F10: =VLOOKUP(Table1[[#This Row],[Product_ID]],Products!A:D,4,FALSE) -> Smartphones | G10: =VLOOKUP(H10,Stores!A:E,5,FALSE) -> Africa | H10: ST-002 | I10: Online | J10: 3 | K10: 1008.99 | L10: 0.05 | M10: Card | N10: 609.39 | O10: =Table1[[#This Row],[Unit_Price]]*Table1[[#This Row],[Quantity]] -> 3026.97 | P10: =Table1[[#This Row],[Revenue]]-Table1[[#This Row],[COGS]] -> 1198.8 | Q10: =Table1[[#This Row],[Profit]]/Table1[[#This Row],[Revenue]] -> 0.3960396 | R10: =Table1[[#This Row],[Cost Price]]*Table1[[#This Row],[Quantity]] -> 1828.17
A11: ORD-10010 | B11: 45696 | C11: Unknown -00001 | D11: Unknown -00001 | E11: PROD-0050 | F11: =VLOOKUP(Table1[[#This Row],[Product_ID]],Products!A:D,4,FALSE) -> Accessories | G11: =VLOOKUP(H11,Stores!A:E,5,FALSE) -> Africa | H11: ST-005 | I11: Physical Store | J11: 1 | K11: 115.43 | L11: 0.2 | M11: Transfer | N11: 85.68 | O11: =Table1[[#This Row],[Unit_Price]]*Table1[[#This Row],[Quantity]] -> 115.43 | P11: =Table1[[#This Row],[Revenue]]-Table1[[#This Row],[COGS]] -> 29.75 | Q11: =Table1[[#This Row],[Profit]]/Table1[[#This Row],[Revenue]] -> 0.25773196 | R11: =Table1[[#This Row],[Cost Price]]*Table1[[#This Row],[Quantity]] -> 85.68
A12: ORD-10011 | B12: 46231 | C12: CUST-00438 | D12: =VLOOKUP(C12,Customers!A:E,5,FALSE) -> Mass Market | E12: PROD-0036 | F12: =VLOOKUP(Table1[[#This Row],[Product_ID]],Products!A:D,4,FALSE) -> Laptops | G12: =VLOOKUP(H12,Stores!A:E,5,FALSE) -> Africa | H12: ST-001 | I12: Online | J12: 1 | K12: 1234.97 | L12: 0 | M12: Transfer | N12: 875.27 | O12: =Table1[[#This Row],[Unit_Price]]*Table1[[#This Row],[Quantity]] -> 1234.97 | P12: =Table1[[#This Row],[Revenue]]-Table1[[#This Row],[COGS]] -> 359.7 | Q12: =Table1[[#This Row],[Profit]]/Table1[[#This Row],[Revenue]] -> 0.29126214 | R12: =Table1[[#This Row],[Cost Price]]*Table1[[#This Row],[Quantity]] -> 875.27
A13: ORD-10012 | B13: 45888 | C13: CUST-00379 | D13: =VLOOKUP(C13,Customers!A:E,5,FALSE) -> Mass Market | E13: PROD-0038 | F13: =VLOOKUP(Table1[[#This Row],[Product_ID]],Products!A:D,4,FALSE) -> Audio | G13: =VLOOKUP(H13,Stores!A:E,5,FALSE) -> South America | H13: ST-018 | I13: Online | J13: 2 | K13: 244.02 | L13: 0 | M13: Transfer | N13: 171.81 | O13: =Table1[[#This Row],[Unit_Price]]*Table1[[#This Row],[Quantity]] -> 488.04 | P13: =Table1[[#This Row],[Revenue]]-Table1[[#This Row],[COGS]] -> 144.42 | Q13: =Table1[[#This Row],[Profit]]/Table1[[#This Row],[Revenue]] -> 0.29591837 | R13: =Table1[[#This Row],[Cost Price]]*Table1[[#This Row],[Quantity]] -> 343.62
A14: ORD-10013 | B14: 46083 | C14: CUST-00041 | D14: =VLOOKUP(C14,Customers!A:E,5,FALSE) -> Mass Market | E14: Unknown- 001 | F14: =VLOOKUP(Table1[[#This Row],[Product_ID]],Products!A:D,4,FALSE) -> #N/A | G14: =VLOOKUP(H14,Stores!A:E,5,FALSE) -> Europe | H14: ST-012 | I14: Online | J14: 3 | K14: 146066 | L14: 0 | M14: Transfer | N14: 0 | O14: 0 | P14: =Table1[[#This Row],[Revenue]]-Table1[[#This Row],[COGS]] -> 0 | Q14: 0 | R14: =Table1[[#This Row],[Cost Price]]*Table1[[#This Row],[Quantity]] -> 0
A15: ORD-10014 | B15: 46156 | C15: CUST-00417 | D15: =VLOOKUP(C15,Customers!A:E,5,FALSE) -> Mass Market | E15: PROD-0040 | F15: =VLOOKUP(Table1[[#This Row],[Product_ID]],Products!A:D,4,FALSE) -> Audio | G15: =VLOOKUP(H15,Stores!A:E,5,FALSE) -> Africa | H15: ST-005 | I15: Online | J15: 5 | K15: 101.97 | L15: 0 | M15: Transfer | N15: 71.28 | O15: =Table1[[#This Row],[Unit_Price]]*Table1[[#This Row],[Quantity]] -> 509.85 | P15: =Table1[[#This Row],[Revenue]]-Table1[[#This Row],[COGS]] -> 153.45 | Q15: =Table1[[#This Row],[Profit]]/Table1[[#This Row],[Revenue]] -> 0.30097087 | R15: =Table1[[#This Row],[Cost Price]]*Table1[[#This Row],[Quantity]] -> 356.4
A16: ORD-10015 | B16: 45882 | C16: CUST-00184 | D16: =VLOOKUP(C16,Customers!A:E,5,FALSE) -> Mass Market | E16: PROD-0048 | F16: =VLOOKUP(Table1[[#This Row],[Product_ID]],Products!A:D,4,FALSE) -> Audio | G16: =VLOOKUP(H16,Stores!A:E,5,FALSE) -> Europe | H16: ST-011 | I16: Physical Store | J16: 4 | K16: 117.81 | L16: 0.02 | M16: Transfer | N16: 82.11 | O16: =Table1[[#This Row],[Unit_Price]]*Table1[[#This Row],[Quantity]] -> 471.24 | P16: =Table1[[#This Row],[Revenue]]-Table1[[#This Row],[COGS]] -> 142.8 | Q16: =Table1[[#This Row],[Profit]]/Table1[[#This Row],[Revenue]] -> 0.3030303 | R16: =Table1[[#This Row],[Cost Price]]*Table1[[#This Row],[Quantity]] -> 328.44
A17: ORD-10016 | B17: 45951 | C17: CUST-00719 | D17: =VLOOKUP(C17,Customers!A:E,5,FALSE) -> Mass Market | E17: PROD-0007 | F17: =VLOOKUP(Table1[[#This Row],[Product_ID]],Products!A:D,4,FALSE) -> Televisions | G17: =VLOOKUP(H17,Stores!A:E,5,FALSE) -> EUROPE | H17: ST-013 | I17: Online | J17: 5 | K17: 1799 | L17: 0.02 | M17: Cash | N17: 1097.39 | O17: =Table1[[#This Row],[Unit_Price]]*Table1[[#This Row],[Quantity]] -> 8995 | P17: =Table1[[#This Row],[Revenue]]-Table1[[#This Row],[COGS]] -> 3508.05 | Q17: =Table1[[#This Row],[Profit]]/Table1[[#This Row],[Revenue]] -> 0.39 | R17: =Table1[[#This Row],[Cost Price]]*Table1[[#This Row],[Quantity]] -> 5486.95
A18: ORD-10017 | B18: 46105 | C18: CUST-00359 | D18: =VLOOKUP(C18,Customers!A:E,5,FALSE) -> Mass Affluent | E18: PROD-0020 | F18: =VLOOKUP(Table1[[#This Row],[Product_ID]],Products!A:D,4,FALSE) -> Smartphones | G18: =VLOOKUP(H18,Stores!A:E,5,FALSE) -> Asia | H18: ST-008 | I18: Online | J18: 1 | K18: 399 | L18: 0.02 | M18: Transfer | N18: 287.28 | O18: =Table1[[#This Row],[Unit_Price]]*Table1[[#This Row],[Quantity]] -> 399 | P18: =Table1[[#This Row],[Revenue]]-Table1[[#This Row],[COGS]] -> 111.72 | Q18: =Table1[[#This Row],[Profit]]/Table1[[#This Row],[Revenue]] -> 0.28 | R18: =Table1[[#This Row],[Cost Price]]*Table1[[#This Row],[Quantity]] -> 287.28
A19: ORD-10018 | B19: 46038 | C19: CUST-00286 | D19: =VLOOKUP(C19,Customers!A:E,5,FALSE) -> Affluent | E19: PROD-0056 | F19: =VLOOKUP(Table1[[#This Row],[Product_ID]],Products!A:D,4,FALSE) -> Accessories | G19: =VLOOKUP(H19,Stores!A:E,5,FALSE) -> Africa | H19: ST-003 | I19: Physical Store | J19: 2 | K19: 157.41 | L19: 0.15 | M19: Transfer | N19: 116.07 | O19: =Table1[[#This Row],[Unit_Price]]*Table1[[#This Row],[Quantity]] -> 314.82 | P19: =Table1[[#This Row],[Revenue]]-Table1[[#This Row],[COGS]] -> 82.68 | Q19: =Table1[[#This Row],[Profit]]/Table1[[#This Row],[Revenue]] -> 0.26262626 | R19: =Table1[[#This Row],[Cost Price]]*Table1[[#This Row],[Quantity]] -> 232.14
A20: ORD-10019 | B20: 46039 | C20: CUST-00029 | D20: =VLOOKUP(C20,Customers!A:E,5,FALSE) -> Mass Market | E20: PROD-0008 | F20: =VLOOKUP(Table1[[#This Row],[Product_ID]],Products!A:D,4,FALSE) -> Televisions | G20: =VLOOKUP(H20,Stores!A:E,5,FALSE) -> Asia | H20: ST-009 | I20: Online | J20: 3 | K20: 2367.97 | L20: 0.05 | M20: Card | N20: 1586.31 | O20: =Table1[[#This Row],[Unit_Price]]*Table1[[#This Row],[Quantity]] -> 7103.91 | P20: =Table1[[#This Row],[Revenue]]-Table1[[#This Row],[COGS]] -> 2344.98 | Q20: =Table1[[#This Row],[Profit]]/Table1[[#This Row],[Revenue]] -> 0.33009709 | R20: =Table1[[#This Row],[Cost Price]]*Table1[[#This Row],[Quantity]] -> 4758.93
A21: ORD-10020 | B21: 45925 | C21: CUST-00611 | D21: =VLOOKUP(C21,Customers!A:E,5,FALSE) -> Mass Market | E21: PROD-0028 | F21: =VLOOKUP(Table1[[#This Row],[Product_ID]],Products!A:D,4,FALSE) -> Laptops | G21: =VLOOKUP(H21,Stores!A:E,5,FALSE) -> Europe | H21: ST-012 | I21: Physical Store | J21: 2 | K21: 999 | L21: 0 | M21: Transfer | N21: 689.31 | O21: =Table1[[#This Row],[Unit_Price]]*Table1[[#This Row],[Quantity]] -> 1998 | P21: =Table1[[#This Row],[Revenue]]-Table1[[#This Row],[COGS]] -> 619.38 | Q21: =Table1[[#This Row],[Profit]]/Table1[[#This Row],[Revenue]] -> 0.31 | R21: =Table1[[#This Row],[Cost Price]]*Table1[[#This Row],[Quantity]] -> 1378.62
A22: ORD-10021 | B22: 46165 | C22: CUST-00195 | D22: =VLOOKUP(C22,Customers!A:E,5,FALSE) -> Mass Affluent | E22: PROD-0017 | F22: =VLOOKUP(Table1[[#This Row],[Product_ID]],Products!A:D,4,FALSE) -> Smartphones | G22: =VLOOKUP(H22,Stores!A:E,5,FALSE) -> Africa | H22: ST-002 | I22: Physical Store | J22: 1 | K22: 969.03 | L22: 0.02 | M22: Transfer | N22: 609.39 | O22: =Table1[[#This Row],[Unit_Price]]*Table1[[#This Row],[Quantity]] -> 969.03 | P22: =Table1[[#This Row],[Revenue]]-Table1[[#This Row],[COGS]] -> 359.64 | Q22: =Table1[[#This Row],[Profit]]/Table1[[#This Row],[Revenue]] -> 0.37113402 | R22: =Table1[[#This Row],[Cost Price]]*Table1[[#This Row],[Quantity]] -> 609.39
A23: ORD-10022 | B23: 46268 | C23: CUST-00072 | D23: =VLOOKUP(C23,Customers!A:E,5,FALSE) -> Mass Market | E23: PROD-0043 | F23: =VLOOKUP(Table1[[#This Row],[Product_ID]],Products!A:D,4,FALSE) -> Audio | G23: =VLOOKUP(H23,Stores!A:E,5,FALSE) -> Europe | H23: ST-011 | I23: Physical Store | J23: 3 | K23: 307.97 | L23: 0 | M23: Transfer | N23: 191.36 | O23: =Table1[[#This Row],[Unit_Price]]*Table1[[#This Row],[Quantity]] -> 923.91 | P23: =Table1[[#This Row],[Revenue]]-Table1[[#This Row],[COGS]] -> 349.83 | Q23: =Table1[[#This Row],[Profit]]/Table1[[#This Row],[Revenue]] -> 0.37864078 | R23: =Table1[[#This Row],[Cost Price]]*Table1[[#This Row],[Quantity]] -> 574.08
A24: ORD-10023 | B24: 46129 | C24: CUST-00317 | D24: =VLOOKUP(C24,Customers!A:E,5,FALSE) -> Mass Market | E24: PROD-0043 | F24: =VLOOKUP(Table1[[#This Row],[Product_ID]],Products!A:D,4,FALSE) -> Audio | G24: =VLOOKUP(H24,Stores!A:E,5,FALSE) -> North America | H24: ST-014 | I24: Physical Store | J24: 2 | K24: 304.98 | L24: 0.05 | M24: Transfer | N24: 191.36 | O24: =Table1[[#This Row],[Unit_Price]]*Table1[[#This Row],[Quantity]] -> 609.96 | P24: =Table1[[#This Row],[Revenue]]-Table1[[#This Row],[COGS]] -> 227.24 | Q24: =Table1[[#This Row],[Profit]]/Table1[[#This Row],[Revenue]] -> 0.37254902 | R24: =Table1[[#This Row],[Cost Price]]*Table1[[#This Row],[Quantity]] -> 382.72
A25: ORD-10024 | B25: 45787 | C25: CUST-00197 | D25: =VLOOKUP(C25,Customers!A:E,5,FALSE) -> Mass Market | E25: PROD-0027 | F25: =VLOOKUP(Table1[[#This Row],[Product_ID]],Products!A:D,4,FALSE) -> Laptops | G25: =VLOOKUP(H25,Stores!A:E,5,FALSE) -> EUROPE | H25: ST-013 | I25: Online | J25: 3 | K25: 1357.03 | L25: 0.05 | M25: Transfer | N25: 853.39 | O25: =Table1[[#This Row],[Unit_Price]]*Table1[[#This Row],[Quantity]] -> 4071.09 | P25: =Table1[[#This Row],[Revenue]]-Table1[[#This Row],[COGS]] -> 1510.92 | Q25: =Table1[[#This Row],[Profit]]/Table1[[#This Row],[Revenue]] -> 0.37113402 | R25: =Table1[[#This Row],[Cost Price]]*Table1[[#This Row],[Quantity]] -> 2560.17
A26: ORD-10025 | B26: 46239 | C26: CUST-00001 | D26: =VLOOKUP(C26,Customers!A:E,5,FALSE) -> Mass Market | E26: PROD-0020 | F26: =VLOOKUP(Table1[[#This Row],[Product_ID]],Products!A:D,4,FALSE) -> Smartphones | G26: =VLOOKUP(H26,Stores!A:E,5,FALSE) -> Asia | H26: ST-010 | I26: Online | J26: 2 | K26: 410.97 | L26: 0.1 | M26: Transfer | N26: 287.28 | O26: =Table1[[#This Row],[Unit_Price]]*Table1[[#This Row],[Quantity]] -> 821.94 | P26: =Table1[[#This Row],[Revenue]]-Table1[[#This Row],[COGS]] -> 247.38 | Q26: =Table1[[#This Row],[Profit]]/Table1[[#This Row],[Revenue]] -> 0.30097087 | R26: =Table1[[#This Row],[Cost Price]]*Table1[[#This Row],[Quantity]] -> 574.56
... A49: ORD-10048 | B49: 46204 | C49: CUST-00111 | D49: =VLOOKUP(C49,Customers!A:E,5,FALSE) -> Mass Market | E49: PROD-0038 | F49: =VLOOKUP(Table1[[#This Row],[Product_ID]],Products!A:D,4,FALSE) -> Audio | G49: =VLOOKUP(H49,Stores!A:E,5,FALSE) -> Africa | H49: ST-001 | I49: Physical Store | J49: 3 | K49: 253.98 | L49: 0.15 | M49: Transfer | N49: 171.81 | O49: =Table1[[#This Row],[Unit_Price]]*Table1[[#This Row],[Quantity]] -> 761.94 | P49: =Table1[[#This Row],[Revenue]]-Table1[[#This Row],[COGS]] -> 246.51 | Q49: =Table1[[#This Row],[Profit]]/Table1[[#This Row],[Revenue]] -> 0.32352941 | R49: =Table1[[#This Row],[Cost Price]]*Table1[[#This Row],[Quantity]] -> 515.43
A50: ORD-10049 | B50: 45941 | C50: CUST-00078 | D50: =VLOOKUP(C50,Customers!A:E,5,FALSE) -> Mass Market | E50: Unknown- 002 | F50: =VLOOKUP(Table1[[#This Row],[Product_ID]],Products!A:D,4,FALSE) -> #N/A | G50: =VLOOKUP(H50,Stores!A:E,5,FALSE) -> Asia | H50: ST-008 | I50: Online | J50: 3 | K50: 375779 | L50: 0.05 | M50: Transfer | N50: 0 | O50: 0 | P50: =Table1[[#This Row],[Revenue]]-Table1[[#This Row],[COGS]] -> 0 | Q50: 0 | R50: =Table1[[#This Row],[Cost Price]]*Table1[[#This Row],[Quantity]] -> 0
A51: ORD-10050 | B51: 45667 | C51: CUST-00580 | D51: =VLOOKUP(C51,Customers!A:E,5,FALSE) -> Mass Affluent | E51: PROD-0051 | F51: =VLOOKUP(Table1[[#This Row],[Product_ID]],Products!A:D,4,FALSE) -> Accessories | G51: =VLOOKUP(H51,Stores!A:E,5,FALSE) -> Africa | H51: ST-002 | I51: Physical Store | J51: 3 | K51: 86.33 | L51: 0.1 | M51: Card | N51: 55.18 | O51: =Table1[[#This Row],[Unit_Price]]*Table1[[#This Row],[Quantity]] -> 258.99 | P51: =Table1[[#This Row],[Revenue]]-Table1[[#This Row],[COGS]] -> 93.45 | Q51: =Table1[[#This Row],[Profit]]/Table1[[#This Row],[Revenue]] -> 0.36082474 | R51: =Table1[[#This Row],[Cost Price]]*Table1[[#This Row],[Quantity]] -> 165.54
A52: ORD-10051 | B52: 46129 | C52: CUST-00664 | D52: =VLOOKUP(C52,Customers!A:E,5,FALSE) -> Premium | E52: PROD-0022 | F52: =VLOOKUP(Table1[[#This Row],[Product_ID]],Products!A:D,4,FALSE) -> Smartphones | G52: =VLOOKUP(H52,Stores!A:E,5,FALSE) -> Africa | H52: ST-001 | I52: Physical Store | J52: 4 | K52: 1286.01 | L52: 0 | M52: Transfer | N52: 883.32 | O52: =Table1[[#This Row],[Unit_Price]]*Table1[[#This Row],[Quantity]] -> 5144.04 | P52: =Table1[[#This Row],[Revenue]]-Table1[[#This Row],[COGS]] -> 1610.76 | Q52: =Table1[[#This Row],[Profit]]/Table1[[#This Row],[Revenue]] -> 0.31313131 | R52: =Table1[[#This Row],[Cost Price]]*Table1[[#This Row],[Quantity]] -> 3533.28
A53: ORD-10052 | B53: 46055 | C53: CUST-00651 | D53: =VLOOKUP(C53,Customers!A:E,5,FALSE) -> Mass Affluent | E53: PROD-0058 | F53: =VLOOKUP(Table1[[#This Row],[Product_ID]],Products!A:D,4,FALSE) -> Accessories | G53: =VLOOKUP(H53,Stores!A:E,5,FALSE) -> North America | H53: ST-015 | I53: Online | J53: 2 | K53: 80.58 | L53: 0.05 | M53: Transfer | N53: 54.51 | O53: =Table1[[#This Row],[Unit_Price]]*Table1[[#This Row],[Quantity]] -> 161.16 | P53: =Table1[[#This Row],[Revenue]]-Table1[[#This Row],[COGS]] -> 52.14 | Q53: =Table1[[#This Row],[Profit]]/Table1[[#This Row],[Revenue]] -> 0.32352941 | R53: =Table1[[#This Row],[Cost Price]]*Table1[[#This Row],[Quantity]] -> 109.02
A54: ORD-10053 | B54: 46086 | C54: CUST-00794 | D54: =VLOOKUP(C54,Customers!A:E,5,FALSE) -> Mass Affluent | E54: PROD-0031 | F54: =VLOOKUP(Table1[[#This Row],[Product_ID]],Products!A:D,4,FALSE) -> Laptops | G54: =VLOOKUP(H54,Stores!A:E,5,FALSE) -> North America | H54: ST-015 | I54: Physical Store | J54: 4 | K54: 1599 | L54: 0.05 | M54: Transfer | N54: 991.38 | O54: =Table1[[#This Row],[Unit_Price]]*Table1[[#This Row],[Quantity]] -> 6396 | P54: =Table1[[#This Row],[Revenue]]-Table1[[#This Row],[COGS]] -> 2430.48 | Q54: =Table1[[#This Row],[Profit]]/Table1[[#This Row],[Revenue]] -> 0.38 | R54: =Table1[[#This Row],[Cost Price]]*Table1[[#This Row],[Quantity]] -> 3965.52
A55: ORD-10054 | B55: 45759 | C55: CUST-00089 | D55: =VLOOKUP(C55,Customers!A:E,5,FALSE) -> VIP | E55: PROD-0018 | F55: =VLOOKUP(Table1[[#This Row],[Product_ID]],Products!A:D,4,FALSE) -> Smartphones | G55: =VLOOKUP(H55,Stores!A:E,5,FALSE) -> North America | H55: ST-015 | I55: Online | J55: 4 | K55: 874.47 | L55: 0.15 | M55: Transfer | N55: 585.81 | O55: =Table1[[#This Row],[Unit_Price]]*Table1[[#This Row],[Quantity]] -> 3497.88 | P55: =Table1[[#This Row],[Revenue]]-Table1[[#This Row],[COGS]] -> 1154.64 | Q55: =Table1[[#This Row],[Profit]]/Table1[[#This Row],[Revenue]] -> 0.33009709 | R55: =Table1[[#This Row],[Cost Price]]*Table1[[#This Row],[Quantity]] -> 2343.24
A56: ORD-10055 | B56: 45884 | C56: CUST-00507 | D56: =VLOOKUP(C56,Customers!A:E,5,FALSE) -> Mass Market | E56: PROD-0055 | F56: =VLOOKUP(Table1[[#This Row],[Product_ID]],Products!A:D,4,FALSE) -> Accessories | G56: =VLOOKUP(H56,Stores!A:E,5,FALSE) -> Europe | H56: ST-011 | I56: Online | J56: 2 | K56: 97.02 | L56: 0.1 | M56: Transfer | N56: 65.34 | O56: =Table1[[#This Row],[Unit_Price]]*Table1[[#This Row],[Quantity]] -> 194.04 | P56: =Table1[[#This Row],[Revenue]]-Table1[[#This Row],[COGS]] -> 63.36 | Q56: =Table1[[#This Row],[Profit]]/Table1[[#This Row],[Revenue]] -> 0.32653061 | R56: =Table1[[#This Row],[Cost Price]]*Table1[[#This Row],[Quantity]] -> 130.68
A57: ORD-10056 | B57: 46044 | C57: CUST-00287 | D57: =VLOOKUP(C57,Customers!A:E,5,FALSE) -> VIP | E57: PROD-0057 | F57: =VLOOKUP(Table1[[#This Row],[Product_ID]],Products!A:D,4,FALSE) -> Accessories | G57: =VLOOKUP(H57,Stores!A:E,5,FALSE) -> oceania | H57: ST-020 | I57: Physical Store | J57: 3 | K57: 127.71 | L57: 0.02 | M57: Card | N57: 78.69 | O57: =Table1[[#This Row],[Unit_Price]]*Table1[[#This Row],[Quantity]] -> 383.13 | P57: =Table1[[#This Row],[Revenue]]-Table1[[#This Row],[COGS]] -> 147.06 | Q57: =Table1[[#This Row],[Profit]]/Table1[[#This Row],[Revenue]] -> 0.38383838 | R57: =Table1[[#This Row],[Cost Price]]*Table1[[#This Row],[Quantity]] -> 236.07
A58: ORD-10057 | B58: 45700 | C58: CUST-00738 | D58: =VLOOKUP(C58,Customers!A:E,5,FALSE) -> Mass Affluent | E58: PROD-0027 | F58: =VLOOKUP(Table1[[#This Row],[Product_ID]],Products!A:D,4,FALSE) -> Laptops | G58: =VLOOKUP(H58,Stores!A:E,5,FALSE) -> North America | H58: ST-016 | I58: Online | J58: 3 | K58: 1399 | L58: 0.2 | M58: Transfer | N58: 853.39 | O58: =Table1[[#This Row],[Unit_Price]]*Table1[[#This Row],[Quantity]] -> 4197 | P58: =Table1[[#This Row],[Revenue]]-Table1[[#This Row],[COGS]] -> 1636.83 | Q58: =Table1[[#This Row],[Profit]]/Table1[[#This Row],[Revenue]] -> 0.39 | R58: =Table1[[#This Row],[Cost Price]]*Table1[[#This Row],[Quantity]] -> 2560.17
A59: ORD-10058 | B59: 45908 | C59: CUST-00096 | D59: =VLOOKUP(C59,Customers!A:E,5,FALSE) -> MASS MARKET | E59: PROD-0019 | F59: =VLOOKUP(Table1[[#This Row],[Product_ID]],Products!A:D,4,FALSE) -> Smartphones | G59: =VLOOKUP(H59,Stores!A:E,5,FALSE) -> Asia | H59: ST-008 | I59: Physical Store | J59: 3 | K59: 301.99 | L59: 0.05 | M59: Transfer | N59: 194.35 | O59: =Table1[[#This Row],[Unit_Price]]*Table1[[#This Row],[Quantity]] -> 905.97 | P59: =Table1[[#This Row],[Revenue]]-Table1[[#This Row],[COGS]] -> 322.92 | Q59: =Table1[[#This Row],[Profit]]/Table1[[#This Row],[Revenue]] -> 0.35643564 | R59: =Table1[[#This Row],[Cost Price]]*Table1[[#This Row],[Quantity]] -> 583.05
A60: ORD-10059 | B60: 46144 | C60: CUST-00485 | D60: Unknown-2 | E60: PROD-0036 | F60: =VLOOKUP(Table1[[#This Row],[Product_ID]],Products!A:D,4,FALSE) -> Laptops | G60: =VLOOKUP(H60,Stores!A:E,5,FALSE) -> South America | H60: ST-017 | I60: Physical Store | J60: 2 | K60: 1187.01 | L60: 0.1 | M60: Transfer | N60: 875.27 | O60: =Table1[[#This Row],[Unit_Price]]*Table1[[#This Row],[Quantity]] -> 2374.02 | P60: =Table1[[#This Row],[Revenue]]-Table1[[#This Row],[COGS]] -> 623.48 | Q60: =Table1[[#This Row],[Profit]]/Table1[[#This Row],[Revenue]] -> 0.26262626 | R60: =Table1[[#This Row],[Cost Price]]*Table1[[#This Row],[Quantity]] -> 1750.54
A61: ORD-10060 | B61: 46229 | C61: CUST-00465 | D61: =VLOOKUP(C61,Customers!A:E,5,FALSE) -> Mass Market | E61: PROD-0018 | F61: =VLOOKUP(Table1[[#This Row],[Product_ID]],Products!A:D,4,FALSE) -> Smartphones | G61: =VLOOKUP(H61,Stores!A:E,5,FALSE) -> Asia | H61: ST-010 | I61: Physical Store | J61: 1 | K61: 832.02 | L61: 0.02 | M61: Transfer | N61: 585.81 | O61: =Table1[[#This Row],[Unit_Price]]*Table1[[#This Row],[Quantity]] -> 832.02 | P61: =Table1[[#This Row],[Revenue]]-Table1[[#This Row],[COGS]] -> 246.21 | Q61: =Table1[[#This Row],[Profit]]/Table1[[#This Row],[Revenue]] -> 0.29591837 | R61: =Table1[[#This Row],[Cost Price]]*Table1[[#This Row],[Quantity]] -> 585.81
A62: ORD-10061 | B62: 45667 | C62: CUST-00761 | D62: =VLOOKUP(C62,Customers!A:E,5,FALSE) -> Premium | E62: PROD-0035 | F62: =VLOOKUP(Table1[[#This Row],[Product_ID]],Products!A:D,4,FALSE) -> Laptops | G62: =VLOOKUP(H62,Stores!A:E,5,FALSE) -> Africa | H62: ST-006 | I62: Online | J62: 1 | K62: 1018.98 | L62: 0.2 | M62: Transfer | N62: 659.34 | O62: =Table1[[#This Row],[Unit_Price]]*Table1[[#This Row],[Quantity]] -> 1018.98 | P62: =Table1[[#This Row],[Revenue]]-Table1[[#This Row],[COGS]] -> 359.64 | Q62: =Table1[[#This Row],[Profit]]/Table1[[#This Row],[Revenue]] -> 0.35294118 | R62: =Table1[[#This Row],[Cost Price]]*Table1[[#This Row],[Quantity]] -> 659.34
...

Sheet Customers
A1: Customer_ID | B1: Customer_Name | C1: Gender | D1: Age | E1: Customer_Segment | F1: Country | G1: Region | H1: Registration_Date
A2: CUST-00001 | B2: Linh Ndlovu | C2: Female | D2: 57 | E2: Mass Market | F2: Brazil | G2: South America | H2: 45765
A3: CUST-00002 | B3: Sophia Bello | C3: Male | D3: 25 | E3: Mass Affluent | F3: Morocco | G3: Africa | H3: 29/01/2026
A4: CUST-00003 | B4: Zoe Garcia | C4: Female | D4: 0 | E4: Mass Market | F4: India | G4: Asia | H4: 46097
A5: CUST-00004 | B5: Sofia Jones | C5: Male | D5: 30 | E5: MASS MARKET | F5: Ghana | G5: Africa | H5: 45552
A6: CUST-00005 | B6: Hannah Kumar | C6: Female | D6: 45 | E6: Mass Affluent | F6: Japan | G6: Asia | H6: 2023/09/15
A7: CUST-00006 | B7: Sofia Mensah | C7: Female | D7: 23 | E7: Mass Market | F7: Philippines | G7: Asia | H7: 45972
A8: CUST-00007 | B8: Ada Dlamini | C8: Male | D8: 53 | E8: Mass Affluent | F8: Kenya | G8: Africa | H8: 45669
A9: CUST-00008 | B9: Evelyn Kumar | C9: Male | D9: 72 | E9: Premium | F9: Philippines | G9: Asia | H9: 46054
A10: CUST-00009 | B10: Ada Suzuki | C10: Female | D10: 46 | E10: Mass Affluent | F10: Malaysia | G10: Asia | H10: 45503
A11: CUST-00010 | B11: Tunde Wang | C11: Female | D11: 28 | E11: Affluent | F11: Colombia | G11: South America | H11: 46123
A12: CUST-00011 | B12: Linh Okafor | C12: Male | D12: 66 | E12: Mass Affluent | F12: South Africa | G12: Africa | H12: 45837
A13: CUST-00012 | B13: Jason Singh | C13: Female | D13: 36 | E13: Mass Affluent | F13: Australia | G13: Oceania | H13: 45865
A14: CUST-00013 | B14: Ifeoma Haddad | C14: Male | D14: 58 | E14: Mass Market | F14: Nigeria | G14: Africa | H14: 46182
A15: CUST-00014 | B15: Charles Adeyemi | C15: Male | D15: 27 | E15: Premium | F15: Brazil | G15: South America | H15: 45663
A16: CUST-00015 | B16: Anthony Walker | C16: Female | D16: 24 | E16: Mass Market | F16: Kenya | G16: africa | H16: 45444
A17: CUST-00016 | B17: Sofia Chen | C17: Male | D17: 71 | E17: Mass Market | F17: Brazil | G17: South America | H17: 45639
A18: CUST-00017 | B18: Isabella Santos | C18: Female | D18: 70 | E18: Affluent | F18: India | G18: Asia | H18: 46064
... A26: CUST-00025 | B26: Mei Garcia | C26: Female | D26: 51 | E26: Mass Affluent | F26: South Africa | G26: Africa | H26: 46118
A27: CUST-00026 | B27: Sophia Costa | C27: Male | D27: 38 | E27: Mass Market | F27: Australia | G27: Oceania
A28: CUST-00027 | B28: Thomas Davis | C28: Female | D28: 60 | E28: Mass Market | F28: Malaysia | G28: Asia | H28: 46202
A29: CUST-00028 | B29: Aisha Park | C29: Female | D29: 26 | E29: Mass Market | F29: Singapore | G29: Asia | H29: 45360
A30: CUST-00029 | B30: Lily Lim | C30: Female | D30: 68 | E30: Mass Market | F30: China | G30: Asia | H30: 45778
A31: CUST-00030 | B31: Eric Tran | C31: Female | D31: 48 | E31: Mass Market | F31: United States | G31: North America | H31: 45386
A32: CUST-00031 | B32: Sofia Sharma | C32: Female | D32: 53 | E32: Mass Market | F32: Nigeria | G32: Africa | H32: 46200
A33: CUST-00032 | B33: Nur Adeyemi | C33: Female | D33: 55 | E33: Mass Affluent | F33: Italy | G33: Europe | H33: 45783
A34: CUST-00033 | B34: Linh Anderson | C34: Male | D34: 64 | E34: Mass Market | F34: Ghana | G34: Africa | H34: 45005
A35: CUST-00034 | B35: Grace White | C35: Female | D35: 20 | E35: Premium | F35: South Africa | G35: Africa | H35: 45214
A36: CUST-00035 | B36: Aria Brown | C36: Male | D36: 22 | E36: Mass Affluent | F36: United Kingdom | G36: Europe | H36: 46118
A37: CUST-00036 | B37: Brian Walker | C37: Female | D37: 41 | E37: Mass Market | F37: Mexico | G37: North America | H37: 45127
A38: CUST-00037 | B38: Emma Okafor | C38: Female | D38: 19 | E38: Affluent | F38: Chile | G38: South America | H38: 05/03/2024
A39: CUST-00038 | B39: Harper Sato | D39: 52 | E39: Mass Market | F39: Egypt | G39: Africa | H39: 45930
A40: CUST-00039 | B40: John Williams | C40: Male | D40: 59 | E40: Mass Market | F40: Colombia | G40: South America | H40: 10/08/2025
A41: CUST-00040 | B41: David Singh | C41: Female | D41: 47 | E41: Mass Market | F41: Morocco | G41: Africa | H41: 46157
A42: CUST-00041 | B42: Charlotte Sato | C42: Female | D42: 34 | E42: Mass Market | F42: Kenya | G42: Africa | H42: 45848
A43: CUST-00042 | B43: Amelia Miller | C43: Female | D43: 69 | E43: Mass Market | G43: North America | H43: 45904
A44: CUST-00043 | B44: Sofia Hassan | C44: MALE | D44: 51 | E44: Mass Market | F44: Mexico | G44: North America | H44: 46068
A45: CUST-00044 | B45: Ngozi Sharma | C45: Female | D45: 72 | E45: Mass Market | F45: Spain | G45: Europe | H45: 45190
A46: CUST-00045 | B46: Sophia Moore | C46: Male | D46: 46 | E46: Mass Affluent | F46: Chile | G46: South America | H46: 45848
A47: CUST-00046 | B47: Fatima Wilson | C47: Female | D47: 26 | E47: VIP | F47: Netherlands | G47: Europe | H47: 46201
...

Sheet Products
A1: Product_ID | B1: Product_Name | C1: Category | D1: Sub_Category | E1: Cost_Price | F1: Supplier
A2: PROD-0001 | B2: Smart LED TV | C2: Electronics | D2: Televisions | E2: 433.38 | F2: Vertex Supply Co.
A3: PROD-0002 | B3: Smart LED TV Pro | C3: Electronics | D3: Televisions | E3: 679.32 | F3: GlobalTech Supply
A4: PROD-0003 | B4: 4K Smart TV | C4: Electronics | D4: Televisions | E4: 767.36 | F4: Nova Electronics
A5: PROD-0004 | B5: 4K Smart TV Pro | C5: Electronics | D5: Televisions | E5: 1064.29 | F5: Pacific Traders
A6: PROD-0005 | B6: 4K Smart TV Pro | C6: Electronics | D6: Televisions | E6: 989.34 | F6: BlueWave Imports
A7: PROD-0006 | B7: QLED TV | C7: Electronics | D7: Televisions | E7: 948.27 | F7: Prime Distribution
A8: PROD-0007 | B8: OLED TV | C8: Electronics | D8: Televisions | E8: 1097.39 | F8: EastWest Distribution
A9: PROD-0008 | B9: OLED TV Pro | C9: Electronics | D9: Televisions | E9: 1586.31 | F9: Metro Wholesale
A10: PROD-0009 | B10: OLED TV Plus | C10: Electronics | D10: Televisions | E10: 1299.35 | F10: Apex Goods
A11: PROD-0010 | B11: QLED TV | C11: Electronics | D11: Televisions | E11: 1007.28 | F11: Horizon Supplies
A12: PROD-0011 | B12: QLED TV Pro | C12: Electronics | D12: Televisions | E12: 1177.38 | F12: Vertex Supply Co.
A13: PROD-0012 | B13: QLED TV Plus | C13: Electronics | D13: Televisions | E13: 1427.32 | F13: GlobalTech Supply
... A61: PROD-0060 | B61: Webcam Plus | C61: Electronics | D61: Accessories | E61: 78.48 | F61: Horizon Supplies

Sheet Stores
A1: Store_ID | B1: Store_Name | C1: City | D1: Country | E1: Region | F1: Store_Type | G1: Manager
A2: ST-001 | B2: NovaMart Lagos Central | C2: Lagos | D2: NIGERIA | E2: Africa | F2: Flagship | G2: Amara Okafor
A3: ST-002 | B3: NovaMart Abuja City | C3: Abuja | D3: Nigeria | E3: Africa | F3: Standard | G3: Daniel Bello
A4: ST-003 | B4: NovaMart Johannesburg | C4: Johannesburg | D4: south africa | E4: Africa | F4: Flagship | G4: Thabo Mokoena
A5: ST-004 | B5: NovaMart Cape Town | C5: Cape Town | D5: South Africa | E5: Africa | F5: Standard | G5: Lerato Dlamini
A6: ST-005 | B6: NovaMart Nairobi | C6: Nairobi | D6: Kenya | E6: Africa | F6: standard | G6: Brian Mwangi
A7: ST-006 | B7: NovaMart Accra | C7: Accra | D7: Ghana | E7: Africa | F7: Outlet | G7: Kwame Mensah
A8: ST-007 | B8: NovaMart Mumbai | C8: Mumbai | D8: India | E8: Asia | F8: Flagship | G8: Priya Sharma
A9: ST-008 | B9: NovaMart Singapore Central | C9: singapore | D9: Singapore | E9: Asia | F9: Flagship | G9: Daniel Tan
A10: ST-009 | B10: NovaMart Tokyo | C10: tokyo | D10: Japan | E10: Asia | F10: Standard | G10: Yuki Sato
A11: ST-010 | B11: NovaMart Kuala Lumpur | C11: Kuala Lumpur | D11: Malaysia | E11: Asia | F11: Standard | G11: Nur Rahman
A12: ST-011 | B12: NovaMart London | C12: London | D12: United Kingdom | E12: Europe | F12: FLAGSHIP | G12: Emma Williams
... A14: ST-013 | B14: NovaMart Paris | C14: Paris | D14: France | E14: EUROPE | F14: Standard | G14: Claire Martin
A15: ST-014 | B15: NovaMart New York | C15: New York | D15: United States | E15: North America | F15: Flagship
A16: ST-015 | B16: NovaMart Toronto | C16: Toronto | D16: Canada | E16: North America | F16: Standard | G16: Olivia Brown
A17: ST-016 | B17: NovaMart Mexico City | C17: Mexico City | D17: Mexico | E17: North America | F17: Outlet
A18: ST-017 | B18: NovaMart São Paulo | C18: São Paulo | D18: Brazil | E18: South America | F18: Flagship | G18: Lucas Silva
A19: ST-018 | B19: NovaMart Buenos Aires | C19: Buenos Aires | D19: Argentina | E19: South America | F19: standard | G19: Sofia Martinez
A20: ST-019 | B20: NovaMart Sydney | C20: Sydney | D20: Australia | E20: Oceania | F20: Flagship | G20: Jack Taylor
A21: ST-020 | B21: NovaMart Auckland | C21: Auckland | D21: New Zealand | E21: oceania | F21: Standard | G21: Mia Wilson

Sheet Pivot Tables
A2: Total Sale and Profit | F2: Monthly sales trend | O2: Product by revenue and Profit | AB2: Region by Revenue and Profit | BD2: Customer Segement by Revenue and Profit
A3: Revenue | B3: Average of Profit Margin | C3: Sum of Profit | D3: Sum of COGS | AQ3: Row Labels | AR3: Revenue
A4: 7163748.5 | B4: 0.32300081 | C4: 2357640.1 | D4: 4806108.4 | F4: Row Labels | G4: Revenue | O4: Products | P4: P-Revenue | Q4: P-Profit | R4: P-Unit_Price | AQ4: ST-013 | AR4: 436414.83 | BR4: Top 5 Customers by Revenue | CF4: Online Perfomance Compare with Physical Store | CQ4: Profitability
A5: =GETPIVOTDATA(" Revenue",$A$3) -> 7163748.5 | C5: =GETPIVOTDATA("Sum of Profit",$A$3) -> 2357640.1 | D5: =GETPIVOTDATA("Sum of COGS",$A$3) -> 4806108.4 | F5: Jan | G5: 559225.96 | O5: PROD-0033 | P5: 380022.93 | Q5: 136920.21 | R5: 132471.99 | AC5: Regions | AD5: Revenue | AE5: R-Profit | AQ5: ST-004 | AR5: 401065.27 | BD5: Customer Segement | BE5: Revenue | BF5: Profit. | BR5: Row Labels | BS5: Revenue | CE5: .Profit | CF5: Column Labels | CI5: Sum of Revenue | CJ5: Column Labels | CQ5: Sum of Profit Margin | CR5: Column Labels
F6: Feb | G6: 500115.59 | O6: PROD-0009 | P6: 327995.92 | Q6: 114902.52 | R6: 118040.95 | AC6: Africa | AD6: 2230807.5 | AE6: 736587.24 | AQ6: ST-005 | AR6: 395098.03 | BD6: Affluent | BE6: 71701.84 | BF6: 23172.96 | BR6: CUST-00257 | BS6: 41708.01 | CE6: Channel | CF6: Online Store | CG6: Physical Store | CH6: Grand Total | CI6: Channel | CJ6: Online Store | CK6: Physical Store | CL6: Grand Total | CQ6: Row Labels | CR6: Accessories | CS6: Audio | CT6: Laptops | CU6: Smartphones | CV6: Televisions | CW6: #N/A | CX6: Grand Total
F7: Mar | G7: 635411.58 | O7: PROD-0007 | P7: 300990.69 | Q7: 117726.56 | R7: 104324.01 | AC7: Asia | AD7: 1059389 | AE7: 348130.25 | AQ7: ST-018 | AR7: 387126.92 | BD7: PROD-0012 | BE7: 71701.84 | BF7: 23172.96 | BR7: CUST-00384 | BS7: 35114.94 | CE7: 2025 | CF7: 496671.29 | CG7: 479026.66 | CH7: 975697.95 | CI7: 2025 | CJ7: 1492943.6 | CK7: 1461372.1 | CL7: 2954315.6 | CQ7: PROD-0007 | CV7: 22.206967 | CX7: 22.206967
B8: Overall Profit Margin | F8: Apr | G8: 538607.8 | O8: PROD-0012 | P8: 294720.59 | Q8: 94895.79 | R8: 119978.84 | AC8: Asia | AD8: 339356.76 | AE8: 111046.17 | AQ8: ST-006 | AR8: 386093.1 | BD8: Mass Affluent | BE8: 112813.6 | BF8: 30955.78 | BR8: CUST-00395 | BS8: 39948.97 | CE8: 2026 | CF8: 680234.76 | CG8: 701707.38 | CH8: 1381942.1 | CI8: 2026 | CJ8: 2092514.1 | CK8: 2116918.8 | CL8: 4209432.9 | CQ8: PROD-0009 | CV8: 20.669738 | CX8: 20.669738
B9: =GETPIVOTDATA("Sum of Profit",$A$3)/GETPIVOTDATA(" Revenue",$A$3) -> 0.32910704 | F9: May | G9: 580586.48 | O9: PROD-0032 | P9: 294402.12 | Q9: 92533.92 | R9: 100340.37 | AC9: Europe | AD9: 1109903.4 | AE9: 365284.6 | AQ9: ST-020 | AR9: 376169.22 | BD9: PROD-0026 | BE9: 112813.6 | BF9: 30955.78 | BR9: CUST-00473 | BS9: 52971.45 | CE9: Grand Total | CF9: 1176906 | CG9: 1180734 | CH9: 2357640.1 | CI9: Grand Total | CJ9: 3585457.6 | CK9: 3578290.9 | CL9: 7163748.5 | CQ9: PROD-0013 | CU9: 20.79502 | CX9: 20.79502
F10: Jun | G10: 578475.62 | O10: Grand Total | P10: 1598132.3 | Q10: 556979 | R10: 575156.16 | AC10: North America | AD10: 982913.68 | AE10: 320921.51 | AQ10: ST-009 | AR10: 369470.91 | BD10: Mass Market | BE10: 167433 | BF10: 60275.88 | BR10: CUST-00661 | BS10: 35121.3 | CQ10: PROD-0027 | CT10: 20.960759 | CX10: 20.960759
A11: Count of Order_ID | F11: Jul | G11: 671517.29 | AC11: oceania | AD11: 701211.91 | AE11: 233168.26 | AQ11: ST-010 | AR11: 362401.03 | BD11: PROD-0033 | BE11: 167433 | BF11: 60275.88 | BR11: Grand Total | BS11: 204864.67 | CQ11: PROD-0051 | CR11: 22.450686 | CX11: 22.450686
A12: 2960 | F12: Aug | G12: 594498.2 | AC12: South America | AD12: 740166.29 | AE12: 242502.06 | AQ12: ST-001 | AR12: 359916.23 | BD12: Premium | BE12: 61659.18 | BF12: 18828.81 | CQ12: Grand Total | CR12: 22.450686 | CT12: 20.960759 | CU12: 20.79502 | CV12: 42.876705 | CX12: 107.08317
A13: =GETPIVOTDATA("Order_ID",$A$11) -> 2960 | F13: Sep | G13: 528323.22 | AC13: Grand Total | AD13: 7163748.5 | AE13: 2357640.1 | AQ13: ST-017 | AR13: 350158.96 | BD13: PROD-0008 | BE13: 61659.18 | BF13: 18828.81
F14: Oct | G14: 637179.38 | AQ14: ST-003 | AR14: 346794.06 | BD14: VIP | BE14: 28015.26 | BF14: 8576.1
F15: Nov | G15: 601250.87 | AQ15: ST-012 | AR15: 342961.2 | BD15: PROD-0032 | BE15: 28015.26 | BF15: 8576.1
B16: Avg Order Value | F16: Dec | G16: 738556.54 | AQ16: ST-015 | AR16: 342335.78 | BD16: Grand Total | BE16: 441622.88 | BF16: 141809.53
B17: =A5/A13 -> 2420.1853 | F17: Grand Total | G17: 7163748.5 | AQ17: ST-014 | AR17: 339818.2
B18: =B17 -> 2420.1853 | AQ18: ST-007 | AR18: 339356.76
AQ19: ST-002 | AR19: 332465.52
AQ20: ST-008 | AR20: 325960.03
AQ21: ST-019 | AR21: 325042.69
AQ22: ST-011 | AR22: 311484.71
F23: Row Labels | G23: Sum of Profit | O23: Products | P23: Sum of Revenue | Q23: Sum of Profit | AQ23: ST-016 | AR23: 292789.96
F24: Jan | G24: 188017.82 | O24: Affluent | P24: 1030894.4 | Q24: 340580.9 | AQ24: Grand Total | AR24: 7122923.4
F25: Feb | G25: 162502.11 | O25: Mass Affluent | P25: 1630124.3 | Q25: 535547.19
F26: Mar | G26: 206298.15 | O26: Mass Affluent | P26: 4561.68 | Q26: 1627.86
F27: Apr | G27: 176144.78 | O27: Mass Market | P27: 3283703.3 | Q27: 1076302.6
F28: May | G28: 187797.56 | O28: Mass Market | P28: 62011.4 | Q28: 21396.53
F29: Jun | G29: 187636.05 | O29: Premium | P29: 869494.97 | Q29: 291668.06
F30: Jul | G30: 223130.69 | O30: Premium | P30: 20380.46 | Q30: 7051.7
F31: Aug | G31: 194975.49 | O31: VIP | P31: 207193.72 | Q31: 65964.33
F32: Sep | G32: 173439.38 | O32: Grand Total | P32: 7108364.2 | Q32: 2340139.2
F33: Oct | G33: 212357.58
F34: Nov | G34: 201144.45
F35: Dec | G35: 244196.03
F36: Grand Total | G36: 2357640.1

Sheet new dashboard

Sheet new dashboard (2)

Sheet Recommendation
